Workbook

Sheet 시트1
B2: 사고뭉치 WBS | I2: 공식 산출물 일정 반영 · 1주차 10/16~23 · 총 89개 작업
B4: 프로젝트 이름 | D4: 사고뭉치 | I4: 프로젝트 시작 | P4: 46311 | X4: 프로젝트 마감 | AE4: 46364
B5: 프로젝트 관리자 | D5: 김태윤 | I5: 작성 기준일 | P5: 46318 | X5: 전체 일정일 | AE5: =COUNTIFS(I10:AV10,">="&P4,I10:AV10,"<="&AE4) -> 40
B6: 완료율은 실제 확인 후 입력 · 보고·구현·검증·제출 완료를 구분 | I6: 일정일: 평일 + 실제 작업한 10/17~18 · 5단계는 병행 제출 일정 · 기간은 인원 공수가 아님
B8: 작업 계획 | I8: 1~2주 | V8: 3~4주 | AF8: 5~6주 | AP8: 7~8주
B9: 노란색 입력칸: 주 담당 · 시작일 · 마감일 · 실제 완료율 | I9: ="1주 "&TEXT(I10,"m/d")&"~"&TEXT(P10,"m/d") -> 1주 10/16~10/23 | Q9: ="2주 "&TEXT(Q10,"m/d")&"~"&TEXT(U10,"m/d") -> 2주 10/26~10/30 | V9: ="3주 "&TEXT(V10,"m/d")&"~"&TEXT(Z10,"m/d") -> 3주 11/2~11/6 | AA9: ="4주 "&TEXT(AA10,"m/d")&"~"&TEXT(AE10,"m/d") -> 4주 11/9~11/13 | AF9: ="5주 "&TEXT(AF10,"m/d")&"~"&TEXT(AJ10,"m/d") -> 5주 11/16~11/20 | AK9: ="6주 "&TEXT(AK10,"m/d")&"~"&TEXT(AO10,"m/d") -> 6주 11/23~11/27 | AP9: ="7주 "&TEXT(AP10,"m/d")&"~"&TEXT(AT10,"m/d") -> 7주 11/30~12/4 | AU9: ="8주"&CHAR(10)&TEXT(AU10,"m/d")&"~"&TEXT(AV10,"d") -> 8주 12/7~8
B10: WBS 번호 | C10: 작업 제목 | D10: 주 담당 | E10: 시작일 | F10: 마감일 | G10: 기간 (일정일) | H10: 완료율 | I10: =$P$4 -> 46311 | J10: =I10+1 -> 46312 | K10: =J10+1 -> 46313 | L10: =K10+1 -> 46314 | M10: =L10+1 -> 46315 | N10: =M10+1 -> 46316 | O10: =N10+1 -> 46317 | P10: =O10+1 -> 46318 | Q10: =WORKDAY(P10,1) -> 46321 | R10: =WORKDAY(Q10,1) -> 46322 | S10: =WORKDAY(R10,1) -> 46323 | T10: =WORKDAY(S10,1) -> 46324 | U10: =WORKDAY(T10,1) -> 46325 | V10: =WORKDAY(U10,1) -> 46328 | W10: =WORKDAY(V10,1) -> 46329 | X10: =WORKDAY(W10,1) -> 46330 | ... AV10: =WORKDAY(AU10,1) -> 46364
B11: WBS-1 | C11: 착수·주제 검토·요구사항 확정 | D11: 김태윤 | E11: =MIN(E12:E23) -> 46311 | F11: =MAX(F12:F23) -> 46322 | G11: =COUNTIFS($I$10:$AV$10,">="&E11,$I$10:$AV$10,"<="&F11) -> 10 | H11: =IFERROR(MAX(0,MIN(1,(TODAY()-E11)/(F11-E11))),0) -> 0.63636364
B12: WBS-1.1 | C12: ='작업 상세'!C8 -> 초기 주제 발굴·기획안 작성 | D12: 김태윤 | E12: 46311 | F12: 46318 | G12: =IF(OR(E12="",F12=""),"",IF(F12<E12,"기간 확인",COUNTIFS($I$10:$AV$10,">="&E12,$I$10:$AV$10,"<="&F12))) -> 8 | H12: =IFERROR(MAX(0,MIN(1,(TODAY()-E12)/(F12-E12))),0) -> 1
B13: WBS-1.2 | C13: ='작업 상세'!C9 -> 후보 MVP 제작·데이터·경쟁 조사 | D13: 김태윤 | E13: 46312 | F13: 46313 | G13: =IF(OR(E13="",F13=""),"",IF(F13<E13,"기간 확인",COUNTIFS($I$10:$AV$10,">="&E13,$I$10:$AV$10,"<="&F13))) -> 2 | H13: =IFERROR(MAX(0,MIN(1,(TODAY()-E13)/(F13-E13))),0) -> 1
B14: WBS-1.3 | C14: ='작업 상세'!C10 -> 후보 비교·교육 서비스 차별화 검토 | D14: 김태윤 | E14: 46314 | F14: 46318 | G14: =IF(OR(E14="",F14=""),"",IF(F14<E14,"기간 확인",COUNTIFS($I$10:$AV$10,">="&E14,$I$10:$AV$10,"<="&F14))) -> 5 | H14: =IFERROR(MAX(0,MIN(1,(TODAY()-E14)/(F14-E14))),0) -> 1
B15: WBS-1.4 | C15: ='작업 상세'!C11 -> 교육 MVP·기존 산출물 현황 정리 | D15: 김태윤 | E15: 46316 | F15: 46317 | G15: =IF(OR(E15="",F15=""),"",IF(F15<E15,"기간 확인",COUNTIFS($I$10:$AV$10,">="&E15,$I$10:$AV$10,"<="&F15))) -> 2 | H15: =IFERROR(MAX(0,MIN(1,(TODAY()-E15)/(F15-E15))),0) -> 1
B16: WBS-1.5 | C16: ='작업 상세'!C12 -> 멘토링 피드백·후속 과제 정리 | D16: 김태윤 | E16: 46316 | F16: 46316 | G16: =IF(OR(E16="",F16=""),"",IF(F16<E16,"기간 확인",COUNTIFS($I$10:$AV$10,">="&E16,$I$10:$AV$10,"<="&F16))) -> 1 | H16: =IFERROR(MAX(0,MIN(1,(TODAY()-E16)/(F16-E16))),0) -> 0
B17: WBS-1.6 | C17: ='작업 상세'!C13 -> 교육 데이터·성취기준 확보 검토 | D17: 김동섭 | E17: 46316 | F17: 46318 | G17: =IF(OR(E17="",F17=""),"",IF(F17<E17,"기간 확인",COUNTIFS($I$10:$AV$10,">="&E17,$I$10:$AV$10,"<="&F17))) -> 3 | H17: =IFERROR(MAX(0,MIN(1,(TODAY()-E17)/(F17-E17))),0) -> 1
B18: WBS-1.7 | C18: ='작업 상세'!C14 -> 기획서·요구사항·WBS 초안 정리 | D18: 김태윤 | E18: 46318 | F18: 46318 | G18: =IF(OR(E18="",F18=""),"",IF(F18<E18,"기간 확인",COUNTIFS($I$10:$AV$10,">="&E18,$I$10:$AV$10,"<="&F18))) -> 1 | H18: =IFERROR(MAX(0,MIN(1,(TODAY()-E18)/(F18-E18))),0) -> 0
B19: WBS-1.8 | C19: ='작업 상세'!C15 -> 계정·자녀·기록 정책 결정 | D19: 최인영 | E19: 46321 | F19: 46322 | G19: =IF(OR(E19="",F19=""),"",IF(F19<E19,"기간 확인",COUNTIFS($I$10:$AV$10,">="&E19,$I$10:$AV$10,"<="&F19))) -> 2 | H19: =IFERROR(MAX(0,MIN(1,(TODAY()-E19)/(F19-E19))),0) -> 0
B20: WBS-1.9 | C20: ='작업 상세'!C16 -> 학습·판정·집계와 확장 정책 결정 | D20: 최성욱 | E20: 46321 | F20: 46322 | G20: =IF(OR(E20="",F20=""),"",IF(F20<E20,"기간 확인",COUNTIFS($I$10:$AV$10,">="&E20,$I$10:$AV$10,"<="&F20))) -> 2 | H20: =IFERROR(MAX(0,MIN(1,(TODAY()-E20)/(F20-E20))),0) -> 0
B21: WBS-1.10 | C21: ='작업 상세'!C17 -> 모델·평가 범위 결정 | D21: 김재현 | E21: 46321 | F21: 46322 | G21: =IF(OR(E21="",F21=""),"",IF(F21<E21,"기간 확인",COUNTIFS($I$10:$AV$10,">="&E21,$I$10:$AV$10,"<="&F21))) -> 2 | H21: =IFERROR(MAX(0,MIN(1,(TODAY()-E21)/(F21-E21))),0) -> 0
B22: WBS-1.11 | C22: ='작업 상세'!C18 -> 운영·리포트·결제 정책 결정 | D22: 김태윤 | E22: 46321 | F22: 46322 | G22: =IF(OR(E22="",F22=""),"",IF(F22<E22,"기간 확인",COUNTIFS($I$10:$AV$10,">="&E22,$I$10:$AV$10,"<="&F22))) -> 2 | H22: =IFERROR(MAX(0,MIN(1,(TODAY()-E22)/(F22-E22))),0) -> 0
B23: WBS-1.12 | C23: ='작업 상세'!C19 -> 범위·우선순위·일정 검토 | D23: 김태윤 | E23: 46322 | F23: 46322 | G23: =IF(OR(E23="",F23=""),"",IF(F23<E23,"기간 확인",COUNTIFS($I$10:$AV$10,">="&E23,$I$10:$AV$10,"<="&F23))) -> 1 | H23: =IFERROR(MAX(0,MIN(1,(TODAY()-E23)/(F23-E23))),0) -> 0
B24: WBS-2 | C24: 화면·데이터·연동 설계 | D24: 김태윤 | E24: =MIN(E25:E33) -> 46323 | F24: =MAX(F25:F33) -> 46331 | G24: =COUNTIFS($I$10:$AV$10,">="&E24,$I$10:$AV$10,"<="&F24) -> 7 | H24: =IFERROR(MAX(0,MIN(1,(TODAY()-E24)/(F24-E24))),0) -> 0
B25: WBS-2.1 | C25: ='작업 상세'!C20 -> 세 역할의 화면·사용 흐름 설계 | D25: 황수빈 | E25: 46323 | F25: 46324 | G25: =IF(OR(E25="",F25=""),"",IF(F25<E25,"기간 확인",COUNTIFS($I$10:$AV$10,">="&E25,$I$10:$AV$10,"<="&F25))) -> 2 | H25: =IFERROR(MAX(0,MIN(1,(TODAY()-E25)/(F25-E25))),0) -> 0
B26: WBS-2.2 | C26: ='작업 상세'!C21 -> 공개 API·연동 계약 설계 | D26: 최인영 | E26: 46323 | F26: 46325 | G26: =IF(OR(E26="",F26=""),"",IF(F26<E26,"기간 확인",COUNTIFS($I$10:$AV$10,">="&E26,$I$10:$AV$10,"<="&F26))) -> 3 | H26: =IFERROR(MAX(0,MIN(1,(TODAY()-E26)/(F26-E26))),0) -> 0
B27: WBS-2.3 | C27: ='작업 상세'!C22 -> 학습·대화·거래 기록 설계 | D27: 최인영 | E27: 46323 | F27: 46325 | G27: =IF(OR(E27="",F27=""),"",IF(F27<E27,"기간 확인",COUNTIFS($I$10:$AV$10,">="&E27,$I$10:$AV$10,"<="&F27))) -> 3 | H27: =IFERROR(MAX(0,MIN(1,(TODAY()-E27)/(F27-E27))),0) -> 0
B28: WBS-2.4 | C28: ='작업 상세'!C23 -> 미션·기준표·예시 답 설계 | D28: 김동섭 | E28: 46323 | F28: 46329 | G28: =IF(OR(E28="",F28=""),"",IF(F28<E28,"기간 확인",COUNTIFS($I$10:$AV$10,">="&E28,$I$10:$AV$10,"<="&F28))) -> 5 | H28: =IFERROR(MAX(0,MIN(1,(TODAY()-E28)/(F28-E28))),0) -> 0
B29: WBS-2.5 | C29: ='작업 상세'!C24 -> 학습 데이터·분할 계획 준비 | D29: 김재현 | E29: 46323 | F29: 46328 | G29: =IF(OR(E29="",F29=""),"",IF(F29<E29,"기간 확인",COUNTIFS($I$10:$AV$10,">="&E29,$I$10:$AV$10,"<="&F29))) -> 4 | H29: =IFERROR(MAX(0,MIN(1,(TODAY()-E29)/(F29-E29))),0) -> 0
B30: WBS-2.6 | C30: ='작업 상세'!C25 -> 인증·권한·동의 설계 | D30: 최인영 | E30: 46325 | F30: 46329 | G30: =IF(OR(E30="",F30=""),"",IF(F30<E30,"기간 확인",COUNTIFS($I$10:$AV$10,">="&E30,$I$10:$AV$10,"<="&F30))) -> 3 | H30: =IFERROR(MAX(0,MIN(1,(TODAY()-E30)/(F30-E30))),0) -> 0
B31: WBS-2.7 | C31: ='작업 상세'!C26 -> 배포·관측·복구 설계 | D31: 김동섭 | E31: 46323 | F31: 46325 | G31: =IF(OR(E31="",F31=""),"",IF(F31<E31,"기간 확인",COUNTIFS($I$10:$AV$10,">="&E31,$I$10:$AV$10,"<="&F31))) -> 3 | H31: =IFERROR(MAX(0,MIN(1,(TODAY()-E31)/(F31-E31))),0) -> 0
B32: WBS-2.8 | C32: ='작업 상세'!C27 -> PG 테스트·구독 연동 설계 | D32: 최인영 | E32: 46325 | F32: 46329 | G32: =IF(OR(E32="",F32=""),"",IF(F32<E32,"기간 확인",COUNTIFS($I$10:$AV$10,">="&E32,$I$10:$AV$10,"<="&F32))) -> 3 | H32: =IFERROR(MAX(0,MIN(1,(TODAY()-E32)/(F32-E32))),0) -> 0
B33: WBS-2.9 | C33: ='작업 상세'!C28 -> 최종 검증·평가 기준 설계 | D33: 김태윤 | E33: 46329 | F33: 46331 | G33: =IF(OR(E33="",F33=""),"",IF(F33<E33,"기간 확인",COUNTIFS($I$10:$AV$10,">="&E33,$I$10:$AV$10,"<="&F33))) -> 3 | H33: =IFERROR(MAX(0,MIN(1,(TODAY()-E33)/(F33-E33))),0) -> 0
B34: WBS-3 | C34: 기능·콘텐츠·모델 구현 | D34: 김태윤 | E34: =MIN(E35:E70) -> 46328 | F34: =MAX(F35:F70) -> 46350 | G34: =COUNTIFS($I$10:$AV$10,">="&E34,$I$10:$AV$10,"<="&F34) -> 17 | H34: =IFERROR(MAX(0,MIN(1,(TODAY()-E34)/(F34-E34))),0) -> 0
B35: WBS-3.1 | C35: ='작업 상세'!C29 -> 개발 환경·서버 기본 구성 | D35: 최인영 | E35: 46328 | F35: 46330 | G35: =IF(OR(E35="",F35=""),"",IF(F35<E35,"기간 확인",COUNTIFS($I$10:$AV$10,">="&E35,$I$10:$AV$10,"<="&F35))) -> 3 | H35: =IFERROR(MAX(0,MIN(1,(TODAY()-E35)/(F35-E35))),0) -> 0
B36: WBS-3.2 | C36: ='작업 상세'!C30 -> 가입·로그인·동의 구현 | D36: 최인영 | E36: 46335 | F36: 46338 | G36: =IF(OR(E36="",F36=""),"",IF(F36<E36,"기간 확인",COUNTIFS($I$10:$AV$10,">="&E36,$I$10:$AV$10,"<="&F36))) -> 4 | H36: =IFERROR(MAX(0,MIN(1,(TODAY()-E36)/(F36-E36))),0) -> 0
B37: WBS-3.3 | C37: ='작업 상세'!C31 -> 자녀 연결·접근 권한 구현 | D37: 최인영 | E37: 46335 | F37: 46339 | G37: =IF(OR(E37="",F37=""),"",IF(F37<E37,"기간 확인",COUNTIFS($I$10:$AV$10,">="&E37,$I$10:$AV$10,"<="&F37))) -> 5 | H37: =IFERROR(MAX(0,MIN(1,(TODAY()-E37)/(F37-E37))),0) -> 0
B38: WBS-3.4 | C38: ='작업 상세'!C32 -> 계정 복구·수정·탈퇴 구현 | D38: 최인영 | E38: 46342 | F38: 46344 | G38: =IF(OR(E38="",F38=""),"",IF(F38<E38,"기간 확인",COUNTIFS($I$10:$AV$10,">="&E38,$I$10:$AV$10,"<="&F38))) -> 3 | H38: =IFERROR(MAX(0,MIN(1,(TODAY()-E38)/(F38-E38))),0) -> 0
B39: WBS-3.5 | C39: ='작업 상세'!C33 -> 자체 미션·기준표 콘텐츠 제작 | D39: 김동섭 | E39: 46330 | F39: 46339 | G39: =IF(OR(E39="",F39=""),"",IF(F39<E39,"기간 확인",COUNTIFS($I$10:$AV$10,">="&E39,$I$10:$AV$10,"<="&F39))) -> 8 | H39: =IFERROR(MAX(0,MIN(1,(TODAY()-E39)/(F39-E39))),0) -> 0
B40: WBS-3.6 | C40: ='작업 상세'!C34 -> 관리자 문제 운영 화면 구현 | D40: 황수빈 | E40: 46335 | F40: 46339 | G40: =IF(OR(E40="",F40=""),"",IF(F40<E40,"기간 확인",COUNTIFS($I$10:$AV$10,">="&E40,$I$10:$AV$10,"<="&F40))) -> 5 | H40: =IFERROR(MAX(0,MIN(1,(TODAY()-E40)/(F40-E40))),0) -> 0
B41: WBS-3.7 | C41: ='작업 상세'!C35 -> 미션 탐색·입력 화면 구현 | D41: 황수빈 | E41: 46335 | F41: 46339 | G41: =IF(OR(E41="",F41=""),"",IF(F41<E41,"기간 확인",COUNTIFS($I$10:$AV$10,">="&E41,$I$10:$AV$10,"<="&F41))) -> 5 | H41: =IFERROR(MAX(0,MIN(1,(TODAY()-E41)/(F41-E41))),0) -> 0
B42: WBS-3.8 | C42: ='작업 상세'!C36 -> 답변 버전·제출 상태 구현 | D42: 최인영 | E42: 46335 | F42: 46339 | G42: =IF(OR(E42="",F42=""),"",IF(F42<E42,"기간 확인",COUNTIFS($I$10:$AV$10,">="&E42,$I$10:$AV$10,"<="&F42))) -> 5 | H42: =IFERROR(MAX(0,MIN(1,(TODAY()-E42)/(F42-E42))),0) -> 0
B43: WBS-3.9 | C43: ='작업 상세'!C37 -> 초안 저장·이어하기 구현 | D43: 최인영 | E43: 46342 | F43: 46344 | G43: =IF(OR(E43="",F43=""),"",IF(F43<E43,"기간 확인",COUNTIFS($I$10:$AV$10,">="&E43,$I$10:$AV$10,"<="&F43))) -> 3 | H43: =IFERROR(MAX(0,MIN(1,(TODAY()-E43)/(F43-E43))),0) -> 0
...

Sheet 작업 상세
A1: 사고뭉치 WBS 작업 상세
A2: 기준: 요구사항 v0.3 151개 · 노션 기록 · 공식 산출물 관리 시트 · 프로젝트 2026-10-16~12-08
A3: 89개 작업. 1주차는 10/16~23, 2주차부터 공식 월~금 구간. 작업과 제출 일정을 분리하고 5단계에서 직접 연결.
A4: 입력: 시트1의 주 담당(D), 시작일(E), 마감일(F), 실제 완료율(H). 주 담당은 이 시트에 자동 연결된다. 작업 제목은 이 시트 C열에서 수정한다.
A5: 10/16~18 활동도 WBS 본문에 포함. 기간은 표시된 일정일 수(평일+실제 주말 작업 2일)이며 인원별 공수·기여 비율이 아님.
A6: 제출 마감: 10/23·10/30·11/06·11/13·11/20·11/27·12/04·12/08. 11/06 중간발표, 12/08 최종발표. 실제 제출·검증 완료는 별도 확인.
A7: WBS 번호 | B7: 단계 | C7: 작업 제목 | D7: 주 담당·협업자 | E7: 선행 작업 | F7: 관련 기능 ID | G7: 산출물 | H7: 완료 조건 | I7: 범위·정책·유의사항
A8: WBS-1.1 | B8: 착수·주제 검토·요구사항 확정 | C8: 초기 주제 발굴·기획안 작성 | D8: ='시트1'!D12&CHAR(10)&"협업: 김동섭, 김재현, 최인영, 최성욱, 황수빈"&CHAR(10)&"전반 관리: 김태윤(PM), 김동섭(APM)" -> 김태윤 협업: 김동섭, 김재현, 최인영, 최성욱, 황수빈 전반 관리: 김태윤(PM), 김동섭(APM) | E8: 없음 | F8: 기획·관리 작업 | G8: 초기 후보 기획안·비교 기준 | H8: 10/16 교육안을 포함한 후보 발굴·기획안 작성·공유 기록을 정리한다. | I8: S01. 실제 10/16 작업을 프로젝트 1주차 WBS에 포함. 다른 후보의 기능을 사고뭉치 구현으로 합치지 않음.
A9: WBS-1.2 | B9: 착수·주제 검토·요구사항 확정 | C9: 후보 MVP 제작·데이터·경쟁 조사 | D9: ='시트1'!D13&CHAR(10)&"협업: 김동섭, 김재현, 최인영, 최성욱, 황수빈"&CHAR(10)&"전반 관리: 김태윤(PM), 김동섭(APM)" -> 김태윤 협업: 김동섭, 김재현, 최인영, 최성욱, 황수빈 전반 관리: 김태윤(PM), 김동섭(APM) | E9: WBS-1.1 | F9: 기획·관리 작업 | G9: 후보별 MVP·조사 결과 | H9: 주말에 수행한 후보별 조사·MVP 보고를 작업으로 반영하고 실제 보고자·기능 범위와 미검증 사항을 기록한다. | I9: S02·S03. 10/17~18 실제 작업, 10/19 공유. 최성욱 원문 본문 날짜 불일치는 확인 필요. 주 담당은 취합·조정 책임이며 개인별 구현 보고자는 진행 근거 표에 보존.
A10: WBS-1.3 | B10: 착수·주제 검토·요구사항 확정 | C10: 후보 비교·교육 서비스 차별화 검토 | D10: ='시트1'!D14&CHAR(10)&"협업: 김동섭, 김재현, 최인영, 최성욱, 황수빈"&CHAR(10)&"전반 관리: 김태윤(PM), 김동섭(APM)" -> 김태윤 협업: 김동섭, 김재현, 최인영, 최성욱, 황수빈 전반 관리: 김태윤(PM), 김동섭(APM) | E10: WBS-1.2 | F10: 기획·관리 작업 | G10: 후보 비교표·교육 서비스 차별화 근거 | H10: 사용자 문제·유사 서비스·데이터 경로·기한 내 구현 가능성을 비교하고 교육안의 단순 GPT 피드백 대비 차이와 미검증 가설을 정리한다. | I10: S04~S06·S09·S10. 다른 후보는 선정 경위로만 보존. B2G/B2B2C·과학/사회/영어 확장은 현재 결정으로 간주하지 않음. / 10/19~23 후보 검토 작업. 이전 주말 MVP 제작과 구분.
A11: WBS-1.4 | B11: 착수·주제 검토·요구사항 확정 | C11: 교육 MVP·기존 산출물 현황 정리 | D11: ='시트1'!D15&CHAR(10)&"협업: 김동섭, 김재현, 최인영, 최성욱, 황수빈"&CHAR(10)&"전반 관리: 김태윤(PM), 김동섭(APM)" -> 김태윤 협업: 김동섭, 김재현, 최인영, 최성욱, 황수빈 전반 관리: 김태윤(PM), 김동섭(APM) | E11: 없음 | F11: 기획·관리 작업 | G11: 교육 MVP 버전·코드·문서·데이터 현황표 | H11: 수업 8개·규칙 피드백·브라우저 기록의 보고를 실제 코드·버전과 대조할 항목으로 정리한다. 계정·서버·AI·운영 요구의 차이를 구분한다. | I11: S07: 10/21 규칙 기반·localStorage MVP 보고. S08: 10/22 별도 MVP 구현 보고. 동일 버전·실행 범위 미확인. 원문 보고를 운영 기능 완료로 처리하지 않음. / 10/21~22 구현·검토 보고 범위를 반영. 요구사항 전체 완료율로 환산하지 않음.
A12: WBS-1.5 | B12: 착수·주제 검토·요구사항 확정 | C12: 멘토링 피드백·후속 과제 정리 | D12: ='시트1'!D16&CHAR(10)&"협업: 김동섭, 김재현, 최인영, 최성욱, 황수빈"&CHAR(10)&"전반 관리: 김태윤(PM), 김동섭(APM)" -> 김태윤 협업: 김동섭, 김재현, 최인영, 최성욱, 황수빈 전반 관리: 김태윤(PM), 김동섭(APM) | E12: 없음 | F12: 기획·관리 작업 | G12: 10/21 멘토링 피드백·후속 과제표 | H12: 루브릭 데이터·유사 서비스·소형 모델 역할·서비스 완성 범위와 10/23 초안 제출 요구를 정리해 담당 작업에 연결한다. | I12: S06. 세션 기록은 확인. 피드백 반영 완료·후속 멘토링 일정 확정·제출 완료는 미확인. 현재 담당 배정 기준으로 후속 작업을 제안.
A13: WBS-1.6 | B13: 착수·주제 검토·요구사항 확정 | C13: 교육 데이터·성취기준 확보 검토 | D13: ='시트1'!D17&CHAR(10)&"협업: 김재현, 최성욱"&CHAR(10)&"전반 관리: 김태윤(PM), 김동섭(APM)" -> 김동섭 협업: 김재현, 최성욱 전반 관리: 김태윤(PM), 김동섭(APM) | E13: 없음 | F13: 기획·관리 작업 | G13: 교육 데이터 확보·권리·성취기준 연결 현황표 | H13: 개념 설명 24항목 예비 대조표와 수업 8개 연결 후보를 정리하고 NCIC·AI-Hub·KICE 등 후보의 원본 확보·이용 조건·채점 기준·전문가 검수 필요를 구분한다. | I13: S05·S07·S10. 조사·예비 매핑 보고를 공식 매핑·원본 확보·학습 데이터 구축 완료로 바꾸지 않음. 본 제작·분할은 2.4·2.5 및 3.5에서 수행.
A14: WBS-1.7 | B14: 착수·주제 검토·요구사항 확정 | C14: 기획서·요구사항·WBS 초안 정리 | D14: ='시트1'!D18&CHAR(10)&"협업: 최성욱, 김동섭"&CHAR(10)&"전반 관리: 김태윤(PM), 김동섭(APM)" -> 김태윤 협업: 최성욱, 김동섭 전반 관리: 김태윤(PM), 김동섭(APM) | E14: WBS-1.4, WBS-1.5, WBS-1.6 | F14: FFJ-01, FBF-01, FBF-02, FBF-03, FFJ-02, FBN-01, FBN-02, FBF-04, FFJ-03, FFJ-04, FFJ-05, FFJ-06, FFJ-07, FFJ-08, FFJ-09, FFJ-10, FFJ-11, FFH-01, FAD-01, FFJ-12, FFJ-13, FFJ-14, FFJ-15, FBF-05, FBF-06, FBN-03, FFJ-16, FBF-07, FFJ-17, FBF-08, FFH-02, FBF-09, FAC-01, FAC-02, FAC-03, FAC-04, FBN-04, FBF-10, FFH-03, FBN-05, FFJ-18, FAC-05, FBF-11, FAC-06, FFJ-19, FFJ-20, FAC-07, FBF-12, FBF-13, FBF-14, FBF-15, FBF-16, FAC-08, FAC-09, FAD-02, FAC-10, FFH-04, FBF-17, FBN-06, FFH-05, FFJ-21, FFH-06, FFH-07, FBN-07, FFH-08, FFH-09, FFH-10, FFJ-22, FFJ-23, FBN-08, FFH-11, FFH-12, FFH-13, FFJ-24, FBF-18, FFH-14, FAD-03, FAD-04, FBN-09, FBF-19, FBN-10, FAD-05, FAC-11, FBN-11, FBF-20, FFJ-25, FBF-21, FBN-12, FFJ-26, FBF-22, FBF-23, FFH-15, FBF-24, FFJ-27, FBF-25, FAR-01, FAR-02, FAR-03, FAR-04, FFH-16, FFJ-28, FAD-06, FBN-13, FBN-14, FBN-15, FBN-16, FBN-17, FBN-18, FBN-19, FBN-20, FAC-12, FAR-05, FBN-21, FBN-22, FBN-23, FFJ-29, FBF-26, FBF-27, FFH-17, FBF-28, FFH-18, FBF-29, FFJ-30, FFJ-31, FBN-24, FFH-19, FFJ-32, FBF-30, FBF-31, FBF-32, FBF-33, FFH-20, FFJ-33, FFJ-34, FBF-34, FBN-25, FFH-21, FBF-35, FBF-36, FAR-06, FAC-13, FAC-14, FAC-15, FAC-16, FFJ-35, FFJ-36, FFJ-37, FFJ-38, FFJ-39, FBF-37, FFJ-40 | G14: 기획서·요구사항 v0.3·WBS 제출본 | H14: 151개 요구사항과 최초 초안 48개의 연결을 유지하고 기능 분해·데이터 확보 상태·담당·일정을 초안에 반영한다. 제출 여부는 별도로 확인한다. | I14: S11·S12. 10/23 제출 일정에 맞춰 기획 초안을 정리한다. 수집 데이터 보고서는 WBS-5.4에서 별도로 제출하며 미확보 데이터를 확보 완료로 작성하지 않음. 제출 사실은 증빙 확인 후 표시.
A15: WBS-1.8 | B15: 착수·주제 검토·요구사항 확정 | C15: 계정·자녀·기록 정책 결정 | D15: ='시트1'!D19&CHAR(10)&"협업: 김태윤, 최성욱"&CHAR(10)&"전반 관리: 김태윤(PM), 김동섭(APM)" -> 최인영 협업: 김태윤, 최성욱 전반 관리: 김태윤(PM), 김동섭(APM) | E15: WBS-1.7 | F15: FFJ-01, FBF-01, FBF-02, FBF-03, FFJ-02, FBN-01, FBN-02, FBF-04, FFJ-25, FBF-21, FBN-12, FFJ-29, FBF-26, FBF-27, FBF-24, FFJ-27, FBF-25 | G15: 계정·자녀 연결·보관 정책 | H15: P01·P02·P05·P09의 결정 또는 보류 사유를 남긴다. | I15: 메모 저장과 시연 링크 방식 검토 필요
A16: WBS-1.9 | B16: 착수·주제 검토·요구사항 확정 | C16: 학습·판정·집계와 확장 정책 결정 | D16: ='시트1'!D20&CHAR(10)&"협업: 김동섭, 김태윤, 김재현"&CHAR(10)&"전반 관리: 김태윤(PM), 김동섭(APM)" -> 최성욱 협업: 김동섭, 김태윤, 김재현 전반 관리: 김태윤(PM), 김동섭(APM) | E16: WBS-1.7 | F16: FFH-01, FAD-01, FFJ-12, FFJ-13, FFJ-14, FFJ-15, FBF-05, FBF-06, FBN-03, FFJ-16, FBF-07, FFJ-17, FBF-08, FFH-02, FBF-09, FAC-01, FAC-02, FAC-03, FAC-04, FBN-04, FBF-10, FBF-14, FBF-15, FBF-16, FAC-08, FAC-09, FAD-02, FAC-10, FFH-04, FBF-17, FBN-06 | G16: 입력·종료·판정·집계 규칙 | H16: P03·P04·P08·P16을 합의하고 미합의 대체 응답은 적용하지 않는다. | I16: 학년·건너뛰기·작은 표본·대체 응답 검토 / S09 암기 카드·간격 복습·확신도·학습 기반 지표는 검토 필요. 현재 151개 요구사항의 확정 구현 범위로 자동 추가하지 않음.
A17: WBS-1.10 | B17: 착수·주제 검토·요구사항 확정 | C17: 모델·평가 범위 결정 | D17: ='시트1'!D21&CHAR(10)&"협업: 황수빈, 김동섭, 최성욱"&CHAR(10)&"전반 관리: 김태윤(PM), 김동섭(APM)" -> 김재현 협업: 황수빈, 김동섭, 최성욱 전반 관리: 김태윤(PM), 김동섭(APM) | E17: WBS-1.6, WBS-1.7 | F17: FAC-13, FAC-14, FAC-15, FAC-16, FAR-01, FAR-02, FAR-03, FAR-04 | G17: M2 필수 범위와 선택 모델 계획 | H17: P11·P15에서 데이터·지표·표본·활성화 범위를 결정한다. | I17: M1·sLLM과 임시 임계값은 조건부 / S06·S10의 설명 정확도·연령별 출력·사람 기준 비교를 평가 범위에 포함할지 결정. 제안·학습 효과와 실측을 구분. / S13: 4번 공통 주제의 자체 sLLM 산출물은 필수로 안내됨. 학습·비교·제출은 11/20까지 계획하고 서비스 공개 활성화는 최종 평가 후 결정.
A18: WBS-1.11 | B18: 착수·주제 검토·요구사항 확정 | C18: 운영·리포트·결제 정책 결정 | D18: ='시트1'!D22&CHAR(10)&"협업: 김동섭, 최인영, 최성욱"&CHAR(10)&"전반 관리: 김태윤(PM), 김동섭(APM)" -> 김태윤 협업: 김동섭, 최인영, 최성욱 전반 관리: 김태윤(PM), 김동섭(APM) | E18: WBS-1.7 | F18: FBN-13, FBN-14, FBN-15, FBN-16, FBN-17, FBN-18, FBN-19, FBN-20, FAC-12, FAR-05, FBN-21, FBN-22, FBN-23, FFH-19, FFJ-32, FBF-30, FBF-31, FBF-32, FBF-33, FFH-20, FFJ-33, FFJ-34, FBF-34, FBN-25, FFH-21, FBF-35, FBF-36, FAR-06, FBF-29, FFJ-30, FFJ-31, FBN-24 | G18: 운영·주간 생성·구독 정책 | H18: P06·P07·P10·P12·P13·P14의 책임과 적용 범위를 기록한다. | I18: 실결제 도입은 PG 계약·승인 후 별도 결정
A19: WBS-1.12 | B19: 착수·주제 검토·요구사항 확정 | C19: 범위·우선순위·일정 검토 | D19: ='시트1'!D23&CHAR(10)&"협업: 김동섭, 김재현, 최인영, 최성욱, 황수빈"&CHAR(10)&"전반 관리: 김태윤(PM), 김동섭(APM)" -> 김태윤 협업: 김동섭, 김재현, 최인영, 최성욱, 황수빈 전반 관리: 김태윤(PM), 김동섭(APM) | E19: WBS-1.3, WBS-1.8, WBS-1.9, WBS-1.10, WBS-1.11 | F19: 기획·관리 작업 | G19: 범위표·일정 초안·역할 배정안 | H19: 핵심·조건부·보류 범위와 확정 담당별 작업량을 검토하고 노션 확장 제안의 채택·보류를 기록한다. | I19: 확정 담당 배정은 유지. S08의 10/22 주제 미정 기록은 과거 상태로 보존하고 현재 사용자 결정인 사고뭉치 진행을 적용한다. S09 확장 제안은 채택·보류 판단 및 작업량 검토 필요.
A20: WBS-2.1 | B20: 화면·데이터·연동 설계 | C20: 세 역할의 화면·사용 흐름 설계 | D20: ='시트1'!D25&CHAR(10)&"협업: 김태윤, 최인영, 최성욱"&CHAR(10)&"전반 관리: 김태윤(PM), 김동섭(APM)" -> 황수빈 협업: 김태윤, 최인영, 최성욱 전반 관리: 김태윤(PM), 김동섭(APM) | E20: WBS-1.12 | F20: FFJ-03, FFJ-04, FFJ-05, FFJ-06, FFJ-07, FFJ-08, FFJ-09, FFJ-10, FFJ-11, FFH-05, FFJ-21, FFH-06, FFH-07, FBN-07, FFH-08, FFH-09, FFH-10, FFJ-22, FFJ-23, FBN-08, FFH-11, FFH-12, FFH-13, FFJ-24, FBF-18 | G20: 화면 흐름도·와이어프레임 | H20: 각 역할의 진입·학습·조회·오류 경로를 연결한다. | I20: 정상 흐름과 빈 기록·권한 거부를 함께 설계
A21: WBS-2.2 | B21: 화면·데이터·연동 설계 | C21: 공개 API·연동 계약 설계 | D21: ='시트1'!D26&CHAR(10)&"협업: 최성욱, 김재현, 황수빈"&CHAR(10)&"전반 관리: 김태윤(PM), 김동섭(APM)" -> 최인영 협업: 최성욱, 김재현, 황수빈 전반 관리: 김태윤(PM), 김동섭(APM) | E21: WBS-1.12 | F21: 기획·관리 작업 | G21: 입출력·오류·상태 계약 | H21: 화면→서버→AI/PG→기록의 생산자·소비자 계약을 정한다. | I21: 구현 계층과 기술 선택은 실제 저장소 규칙에 따른다
A22: WBS-2.3 | B22: 화면·데이터·연동 설계 | C22: 학습·대화·거래 기록 설계 | D22: ='시트1'!D27&CHAR(10)&"협업: 최성욱"&CHAR(10)&"전반 관리: 김태윤(PM), 김동섭(APM)" -> 최인영 협업: 최성욱 전반 관리: 김태윤(PM), 김동섭(APM) | E22: WBS-1.12 | F22: FAD-05, FAC-11, FBN-11, FBF-20 | G22: ERD·답변 버전·근거 연결 설계 | H22: 학생·학습 시도·원문·판정·거래의 경계와 삭제 영향을 정한다. | I22: 실제 아동 정보와 학습 원본의 반입 제한 반영
A23: WBS-2.4 | B23: 화면·데이터·연동 설계 | C23: 미션·기준표·예시 답 설계 | D23: ='시트1'!D28&CHAR(10)&"협업: 최성욱, 황수빈"&CHAR(10)&"전반 관리: 김태윤(PM), 김동섭(APM)" -> 김동섭 협업: 최성욱, 황수빈 전반 관리: 김태윤(PM), 김동섭(APM) | E23: WBS-1.9, WBS-1.6 | F23: FFH-14, FAD-03, FAD-04, FBN-09, FBF-19, FBN-10, FAD-05 | G23: 자체 미션·성취기준·판정 기준표 | H23: 지원 학년·유형·요소·배점·흔한 오답과 공개 조건을 정의한다. | I23: 문항 수와 애니메이션 제작 범위는 승인 범위에 따른다 / S05의 개념 설명 24항목 예비 대조표·수업 8개 연결 후보를 출발점으로 사용. 공식 매핑·전문가 검수 완료로 간주하지 않음.
A24: WBS-2.5 | B24: 화면·데이터·연동 설계 | C24: 학습 데이터·분할 계획 준비 | D24: ='시트1'!D29&CHAR(10)&"협업: 김동섭"&CHAR(10)&"전반 관리: 김태윤(PM), 김동섭(APM)" -> 김재현 협업: 김동섭 전반 관리: 김태윤(PM), 김동섭(APM) | E24: WBS-1.10, WBS-1.6 | F24: FAC-13, FAC-14, FAC-15, FAC-16 | G24: 데이터 구조·문항 그룹 분할 계획 | H24: 데이터 이용 제한을 확인하고 학습·평가 문항을 분리한다. | I24: EDA·전처리 등 구현에 필요한 자료 확인 단계 / S05·S07: NCIC·AI-Hub 원본 확보·이용 조건·교육과정 정합성은 별도 확인. 서비스 문항은 자체 제작 범위 유지.
A25: WBS-2.6 | B25: 화면·데이터·연동 설계 | C25: 인증·권한·동의 설계 | D25: ='시트1'!D30&CHAR(10)&"협업: 김태윤"&CHAR(10)&"전반 관리: 김태윤(PM), 김동섭(APM)" -> 최인영 협업: 김태윤 전반 관리: 김태윤(PM), 김동섭(APM) | E25: WBS-1.8, WBS-2.2, WBS-2.3 | F25: FFJ-01, FBF-01, FBF-02, FBF-03, FFJ-02, FBN-01, FBN-02, FBF-04, FFJ-25, FBF-21, FBN-12, FFJ-29, FBF-26, FBF-27 | G25: 인증·자녀 연결·동의 상태 설계 | H25: 자녀 범위 확인과 관리자 승인·탈퇴 절차를 정한다. | I25: 사용자·관리자·외부 도구의 조회 범위를 동일하게 제한
A26: WBS-2.7 | B26: 화면·데이터·연동 설계 | C26: 배포·관측·복구 설계 | D26: ='시트1'!D31&CHAR(10)&"협업: 김태윤, 최인영, 김재현, 최성욱"&CHAR(10)&"전반 관리: 김태윤(PM), 김동섭(APM)" -> 김동섭 협업: 김태윤, 최인영, 김재현, 최성욱 전반 관리: 김태윤(PM), 김동섭(APM) | E26: WBS-1.11 | F26: FBN-13, FBN-14, FBN-15, FBN-16, FBN-17, FBN-18, FBN-19, FBN-20, FAC-12, FAR-05, FBN-21, FBN-22, FBN-23 | G26: 시스템 구성도·배포·로그·백업·모델 운영 설계 | H26: 경보·비밀 관리·복구·버전 추적의 책임과 기준을 정한다. | I26: 새 서비스나 운영 도구 도입은 선정 후 확정 / S12: 시스템 구성도 10/30 제출. API·ERD 초안과 병행 설계 후 10/30 정합성을 맞춘다.
A27: WBS-2.8 | B27: 화면·데이터·연동 설계 | C27: PG 테스트·구독 연동 설계 | D27: ='시트1'!D32&CHAR(10)&"협업: 황수빈, 김태윤"&CHAR(10)&"전반 관리: 김태윤(PM), 김동섭(APM)" -> 최인영 협업: 황수빈, 김태윤 전반 관리: 김태윤(PM), 김동섭(APM) | E27: WBS-1.11, WBS-2.2, WBS-2.3 | F27: FFH-19, FFJ-32, FBF-30, FBF-31, FBF-32, FBF-33, FFH-20, FFJ-33, FFJ-34, FBF-34, FBN-25, FFH-21, FBF-35, FBF-36, FAR-06 | G27: PG 테스트 연동·구독 상태 설계 | H27: 승인 검증·중복·갱신·해지·환불과 이용 권한 연결을 정한다. | I27: 기본 계획은 테스트 결제, 실결제는 별도 승인 조건
A28: WBS-2.9 | B28: 화면·데이터·연동 설계 | C28: 최종 검증·평가 기준 설계 | D28: ='시트1'!D33&CHAR(10)&"협업: 김동섭, 김재현, 최인영, 최성욱, 황수빈"&CHAR(10)&"전반 관리: 김태윤(PM), 김동섭(APM)" -> 김태윤 협업: 김동섭, 김재현, 최인영, 최성욱, 황수빈 전반 관리: 김태윤(PM), 김동섭(APM) | E28: WBS-2.1, WBS-2.2, WBS-2.3, WBS-2.4, WBS-2.5 | F28: FAR-01, FAR-02, FAR-03, FAR-04, FAR-05, FAR-06 | G28: 검증 시나리오·평가표·실행 구분 | H28: 자동·실제 API·PG 테스트·모델 사람 평가·배포 검증을 구분한다. | I28: 이 단계에서는 기준을 작성하고 구현 중 주기적 시험은 실행하지 않는다 / S06·S10: 규칙·범용 LLM·채택 모델의 설명 정확도, 근거 일치, 정답 선공개, 연령 적합성 비교 기준을 작성한다.
A29: WBS-3.1 | B29: 기능·콘텐츠·모델 구현 | C29: 개발 환경·서버 기본 구성 | D29: ='시트1'!D35&CHAR(10)&"협업: 김동섭"&CHAR(10)&"전반 관리: 김태윤(PM), 김동섭(APM)" -> 최인영 협업: 김동섭 전반 관리: 김태윤(PM), 김동섭(APM) | E29: WBS-2.2, WBS-2.3, WBS-2.7 | F29: FBN-13 | G29: 개발·검증 환경과 서버 구성 | H29: 환경 설정과 비밀 정보 분리를 구현한다. | I29: 실제 동작 검증은 4단계에 모아 수행
A30: WBS-3.2 | B30: 기능·콘텐츠·모델 구현 | C30: 가입·로그인·동의 구현 | D30: ='시트1'!D36&CHAR(10)&"협업: 황수빈"&CHAR(10)&"전반 관리: 김태윤(PM), 김동섭(APM)" -> 최인영 협업: 황수빈 전반 관리: 김태윤(PM), 김동섭(APM) | E30: WBS-3.1, WBS-2.6, WBS-3.34 | F30: FFJ-01, FBF-01, FBF-02, FBF-04 | G30: 계정·인증·동의 기능 | H30: 역할별 진입·로그아웃·만료·동의 상태를 구현한다. | I30: P01 확정 방식 적용
A31: WBS-3.3 | B31: 기능·콘텐츠·모델 구현 | C31: 자녀 연결·접근 권한 구현 | D31: ='시트1'!D37&CHAR(10)&"협업: 황수빈"&CHAR(10)&"전반 관리: 김태윤(PM), 김동섭(APM)" -> 최인영 협업: 황수빈 전반 관리: 김태윤(PM), 김동섭(APM) | E31: WBS-3.1, WBS-2.6, WBS-3.34 | F31: FBF-03, FFJ-02, FBN-01, FBN-02, FBN-05, FBN-06, FBN-07, FBN-08 | G31: 자녀 연결·조회 범위 제어 | H31: 모든 기록·대화 도구·리포트 요청에 동일한 자녀 권한을 적용한다. | I31: 다자녀와 연결 해제 정책 반영
A32: WBS-3.4 | B32: 기능·콘텐츠·모델 구현 | C32: 계정 복구·수정·탈퇴 구현 | D32: ='시트1'!D38&CHAR(10)&"협업: 황수빈"&CHAR(10)&"전반 관리: 김태윤(PM), 김동섭(APM)" -> 최인영 협업: 황수빈 전반 관리: 김태윤(PM), 김동섭(APM) | E32: WBS-3.2, WBS-3.3 | F32: FFJ-25, FBF-21, FBN-12, FFJ-29, FBF-26, FBF-27 | G32: 복구·프로필·삭제 절차 | H32: 본인 확인과 구독·보관 이력을 구분한 삭제 절차를 구현한다. | I32: 미처리 거래와 삭제 정책 연결
A33: WBS-3.5 | B33: 기능·콘텐츠·모델 구현 | C33: 자체 미션·기준표 콘텐츠 제작 | D33: ='시트1'!D39&CHAR(10)&"협업: 최성욱, 황수빈"&CHAR(10)&"전반 관리: 김태윤(PM), 김동섭(APM)" -> 김동섭 협업: 최성욱, 황수빈 전반 관리: 김태윤(PM), 김동섭(APM) | E33: WBS-2.4 | F33: FAD-01, FAD-03, FAD-04, FAD-05 | G33: 미션·장면·예시 답·기준표 | H33: 성취기준·시연 구분·정답 선공개 방지 조건을 콘텐츠에 반영한다. | I33: AI Hub 원문·가공 예시의 서비스 사용 금지 / S07의 자체 제작 수업 8개는 검토·재사용 후보이며 자동으로 납품 콘텐츠 수에 포함하지 않는다.
A34: WBS-3.6 | B34: 기능·콘텐츠·모델 구현 | C34: 관리자 문제 운영 화면 구현 | D34: ='시트1'!D40&CHAR(10)&"협업: 최인영, 김동섭"&CHAR(10)&"전반 관리: 김태윤(PM), 김동섭(APM)" -> 황수빈 협업: 최인영, 김동섭 전반 관리: 김태윤(PM), 김동섭(APM) | E34: WBS-3.1, WBS-2.4, WBS-3.34 | F34: FFJ-10, FFH-14, FBN-09, FBF-19, FBN-10 | G34: 등록·검토·공개·비공개 기능 | H34: 공개 조건·변경 버전·운영 권한과 이력을 구현한다. | I34: 진행 중 학습과 수정본의 적용 시점 구분
A35: WBS-3.7 | B35: 기능·콘텐츠·모델 구현 | C35: 미션 탐색·입력 화면 구현 | D35: ='시트1'!D41&CHAR(10)&"협업: 최인영, 최성욱"&CHAR(10)&"전반 관리: 김태윤(PM), 김동섭(APM)" -> 황수빈 협업: 최인영, 최성욱 전반 관리: 김태윤(PM), 김동섭(APM) | E35: WBS-3.1, WBS-2.1, WBS-2.4 | F35: FFH-01, FFJ-03, FFJ-04, FFJ-12, FFJ-13, FFJ-14, FFJ-15 | G35: 미션 목록·유형별 입력·도움·메모 | H35: 입력 틀·보호자 받아쓰기·진행 위치·메모 이동을 구현한다. | I35: 메모 보관과 시연 링크는 승인 정책 범위만 적용
A36: WBS-3.8 | B36: 기능·콘텐츠·모델 구현 | C36: 답변 버전·제출 상태 구현 | D36: ='시트1'!D42&CHAR(10)&"협업: 최성욱"&CHAR(10)&"전반 관리: 김태윤(PM), 김동섭(APM)" -> 최인영 협업: 최성욱 전반 관리: 김태윤(PM), 김동섭(APM) | E36: WBS-3.1, WBS-2.3, WBS-3.34 | F36: FBF-05, FBF-06, FBF-07, FBF-08 | G36: 최초·추가 답변·상태 기록 | H36: 답변 버전을 보존하고 저장 실패·중복 제출을 구분한다. | I36: AI 처리와 답변 저장 상태 분리
A37: WBS-3.9 | B37: 기능·콘텐츠·모델 구현 | C37: 초안 저장·이어하기 구현 | D37: ='시트1'!D43&CHAR(10)&"협업: 황수빈"&CHAR(10)&"전반 관리: 김태윤(PM), 김동섭(APM)" -> 최인영 협업: 황수빈 전반 관리: 김태윤(PM), 김동섭(APM) | E37: WBS-3.7, WBS-3.8 | F37: FBF-24, FFJ-27, FBF-25, FFJ-05, FFJ-17 | G37: 자동 저장·복원·충돌 처리 | H37: 초안·제출 답변·메모 저장 범위를 구분해 구현한다. | I37: P05 검토 필요 항목 합의 후 적용
A38: WBS-3.10 | B38: 기능·콘텐츠·모델 구현 | C38: 규칙 판정·근거 대조 구현 | D38: ='시트1'!D44&CHAR(10)&"협업: 김재현, 김동섭"&CHAR(10)&"전반 관리: 김태윤(PM), 김동섭(APM)" -> 최성욱 협업: 김재현, 김동섭 전반 관리: 김태윤(PM), 김동섭(APM) | E38: WBS-3.1, WBS-2.4 | F38: FBF-09, FAC-01, FAC-02 | G38: 정답 규칙·요소 판정·보류 처리 | H38: 동치 답·원문 인용·코드 판정·미검증 보류를 구현한다. | I38: LLM 요소 추출과 코드 판정을 분리
A39: WBS-3.11 | B39: 기능·콘텐츠·모델 구현 | C39: 학생 되묻기·대화 구현 | D39: ='시트1'!D45&CHAR(10)&"협업: 황수빈, 최인영"&CHAR(10)&"전반 관리: 김태윤(PM), 김동섭(APM)" -> 최성욱 협업: 황수빈, 최인영 전반 관리: 김태윤(PM), 김동섭(APM) | E39: WBS-3.8, WBS-3.10 | F39: FFH-02, FAC-03, FAC-04, FBN-04, FBF-10 | G39: 학습 대화·금지어 검사·실패 상태 | H39: 답변 근거 기반 질문과 출처·재시도·종료 안내를 구현한다. | I39: P04·P16 미합의 대체 응답을 임의 적용하지 않음
A40: WBS-3.12 | B40: 기능·콘텐츠·모델 구현 | C40: 결과·돌아보기·자기 평가 구현 | D40: ='시트1'!D46&CHAR(10)&"협업: 최성욱, 최인영"&CHAR(10)&"전반 관리: 김태윤(PM), 김동섭(APM)" -> 황수빈 협업: 최성욱, 최인영 전반 관리: 김태윤(PM), 김동섭(APM) | E40: WBS-3.11, WBS-3.5 | F40: FBN-03, FFJ-16, FAD-02, FFJ-38 | G40: 결과 비교·체크리스트·돌아보기 | H40: 근거 구절 체크와 학생 자기 평가를 구분해 저장한다. | I40: 자기 평가는 선택 범위 결정에 따름
...
